Workbook
Name APP: 'SW Sustain Tracking'!$E$90:$E$103
Name BIOS: 'SW Sustain Tracking'!$B$90:$B$103
Name Driver: 'SW Sustain Tracking'!$D$90:$D$103
Name FW: 'SW Sustain Tracking'!$F$90:$F$103
Name VBIOS: 'SW Sustain Tracking'!$C$90:$C$103

Sheet DDIS Dashboard
C1: DDIS Dashboard Data + 柱狀圖
C2: C38 SW Sustain Task Distributed By Customer&Series
C3: Customer | D3: Pass | E3: Fail | F3: Ongoing | G3: Pending | H3: Planning | I3: Total | J3: Pass ratio | K3: Pass ratio w/ 1cycle | L3: Pass ratio w/ regression
C4: C38 NB Gaming
C5: C38 NB Consumer
C6: C38 NB SMB
C7: C38 AIO Consumer
C8: C38 AIO SMB
C9: Total
C11: C38 SW Sustain Task Distributed By Customer and Month
C12: Month | D12: New Test | J12: Regression Test | P12: Total
D13: C38 NB Gaming | E13: C38 NB Consumer | F13: C38 NB SMB | G13: C38 AIO Consumer | H13: C38 AIO SMB | I13: Total | J13: C38 NB Gaming | K13: C38 NB Consumer | L13: C38 NB SMB | M13: C38 AIO Consumer | N13: C38 AIO SMB | O13: Total
C14: Jan
C15: Feb
C16: Mar
C17: Apr
C18: May
C19: Jun
C20: Jul
C21: Aug
C22: Sep
C23: Oct
C24: Nov
C25: Dec
... C28: C38 SW Sustain Task Distributed By Project
C29: C38 NB Project | D29: Pass | E29: Fail | F29: Ongoing | G29: Pending | H29: Planning | I29: Total | J29: Pass ratio | K29: Pass ratio w/ 1cycle | L29: Pass ratio w/ regression
C30: KLG11
C31: KLG10
C32: KLG20
C33: KLG23
C34: KLG13
C35: LLY10
C36: JLG52
C37: KLS71
C38: KLS5I
C39: KLS7I
C40: KLS72 KRK1
C41: ILG50/ILG52
... C53: Total
C54: C38 AIO Project | D54: Pass | E54: Fail | F54: Ongoing | G54: Pending | H54: Planning | I54: Total | J54: Pass ratio | K54: Pass ratio w/ 1cycle | L54: Pass ratio w/ regression
...

Sheet SW Sustain Tracking
B1: APDQA SW Sustaining Tracking Table-2026 | AB1: New Test | AT1: Regression1 Test | BK1: Regression2 Test | CB1: Regression3 Test
B2: 需編輯 | C2: 需編輯,下拉菜單選擇 | G2: 需編輯 | H2: 公式未匹配到值时需手动填写 | L2: 公式，無需編輯 | M2: 公式，無需編輯 | Q2: 需編輯 | R2: 下拉菜單選擇 | S2: 需編輯 | T2: 公式，無需編輯 | W2: 公式，無需編輯 | X2: 需編輯 | Y2: 公式，無需編輯 | Z2: 需編輯(優化後) | AA2: 公式，無需編輯 | AB2: 需編輯,下拉菜單選擇 | AF2: 需編輯 | AG2: 需編輯 | AH2: 需編輯 | AI2: 需編輯 | AJ2: 公式，無需編輯 | AK2: 需編輯 | AT2: 需編輯,下拉菜單選擇 | AX2: 需編輯 | AY2: 需編輯 | AZ2: 需編輯 | BA2: 需編輯 | BB2: 公式，無需編輯 | BC2: 需編輯 | BK2: 需編輯,下拉菜單選擇 | BO2: 需編輯 | BP2: 需編輯 | BQ2: 需編輯 | BR2: 需編輯 | BS2: 公式，無需編輯 | BT2: 需編輯 | CB2: 需編輯,下拉菜單選擇 | CF2: 需編輯 | CG2: 需編輯 | CH2: 需編輯 | CI2: 需編輯 | CJ2: 公式，無需編輯 | CK2: 需編輯
B3: Task No | C3: Year | D3: Month | E3: Customer | F3: Series | G3: Project Code | H3: Project Name | I3: MP Date | J3: EOP Or Not | K3: EOP Date | L3: EOS Date | M3: Project Status | N3: MP Year | O3: EOP Year | P3: EOS Year | Q3: Leverage Project | R3: Test Units status (New build/SIT units/SIT units rework/Others) | S3: Unit_Qty | T3: Total Test Resource | U3: Total Actual Workload(Hrs) | V3: Total Leverage Workload(Hrs) | W3: Final Test Status | X3: Task Closure Date | Y3: Task Leading Time (Days) | Z3: Total Planning Workload(Hrs) | AA3: Total waste time (Hrs) | AB3: Test Stage (New Test/Regression) | AC3: Test Status | AD3: Test Category | AE3: Category Info | AF3: Test Version | AG3: Test Condition (BIOS/Image/OS) | AH3: Driver cut in format | AI3: Issue Link | AJ3: Test Resource | AK3: Actual Workload(Hrs) | AL3: Leverage Workload(Hrs) | AM3: Test Team | AN3: Test_Owner | AO3: Test_Start | AP3: Test_End | AQ3: Working Day | AR3: Change list | AS3: Remark | AT3: Test Stage (New Test/Regression) | AU3: Test Status | AV3: Test Category | AW3: Category Info | AX3: Test Version | AY3: Test Condition (BIOS/Image/OS) | AZ3: Driver cut in format | BA3: Issue Link | BB3: Test Resource | BC3: Actual Workload(Hrs) | BD3: Leverage Workload(Hrs) | BE3: Test_Owner | BF3: Test_Start | BG3: Test_End | BH3: Working Day | BI3: Change list | BJ3: Remark | BK3: Test Stage (New Test/Regression) | BL3: Test Status | BM3: Test Category | BN3: Category Info | BO3: Test Version | BP3: Test Condition (BIOS/Image/OS) | BQ3: Driver cut in format | BR3: Issue Link | BS3: Test Resource | BT3: Actual Workload(Hrs) | BU3: Leverage Workload(Hrs) | BV3: Test_Owner | BW3: Test_Start | BX3: Test_End | BY3: Working Day | BZ3: Change list | CA3: Remark | CB3: Test Stage (New Test/Regression) | CC3: Test Status | CD3: Test Category | CE3: Category Info | CF3: Test Version | CG3: Test Condition (BIOS/Image/OS) | CH3: Driver cut in format | CI3: Issue Link | CJ3: Test Resource | CK3: Actual Workload(Hrs) | CL3: Leverage Workload(Hrs) | CM3: Test_Owner | CN3: Test_Start | CO3: Test_End | CP3: Working Day | CQ3: Change list | CR3: Remark
B4: Link | C4: Start Insert | M4: =IF(COUNT(I4,K4,L4)=0, "", IF(TODAY()<I4,"NPI",IF(TODAY()<K4,"MP",IF(TODAY()<L4,"EOP","EOS")))) | N4: =IF(M4="MP",(TODAY()-I4)/365,"NA") -> NA | O4: =IF(M4="EOP",(TODAY()-K4)/365,"NA") -> NA | P4: =IF(M4="EOS",(TODAY()-L4)/365,"NA") -> NA | T4: =AJ4+BB4+BS4+CJ4 -> 0 | U4: =AK4+BC4+BT4+CK4 -> 0 | V4: =AL4+BD4+BU4+CL4 -> 0 | W4: =IF(COUNTA(AC4,AU4,BL4,CC4)=0,"",IF(CC4<>"",CC4,IF(BL4<>"",BL4,IF(AU4<>"",AU4,AC4)))) | AA4: =IF(AK4+BC4+BT4+CK4-Z4>=0,AK4+BC4+BT4+CK4-Z4,0) -> 0 | AJ4: =IF(AK4=0,0,AK4/AQ4/7) -> 0 | BB4: =IF(BC4=0,0,BC4/BH4/7) -> 0 | BS4: =IF(BT4=0,0,BT4/BY4/7) -> 0 | CJ4: =IF(CK4=0,0,CK4/CP4/7) -> 0
B5: C38 AIO_202605_14 | C5: 2026 | D5: May | E5: C38 AIO | F5: Consumer | G5: LOC22 | H5: =IFERROR(VLOOKUP(G5,'C38 NB project list'!F:J,2,0),IFERROR(VLOOKUP(G5, 'C38 AIO project list'!E:I,2,0),"")) -> IdeaCentre AIO 24AKP10 | I5: =IFERROR(VLOOKUP(G5,'C38 NB project list'!F:J,4,0),IFERROR(VLOOKUP(G5, 'C38 AIO project list'!E:I,4,0),"")) -> 45835 | J5: =IF(K5<=TODAY(),"Y","N") -> N | K5: =IFERROR(VLOOKUP(G5,'C38 NB project list'!F:J,5,0),IFERROR(VLOOKUP(G5,'C38 AIO project list'!E:I,5,0),"")) -> 46660 | L5: =IF(ISNUMBER(K5),EDATE(K5,60),"") -> 48487 | M5: =IF(COUNT(I5,K5,L5)=0, "", IF(TODAY()<I5,"NPI",IF(TODAY()<K5,"MP",IF(TODAY()<L5,"EOP","EOS")))) -> MP | N5: =IF(M5="MP",(TODAY()-I5)/365,"NA") -> 0.9369863 | O5: =IF(M5="EOP",(TODAY()-K5)/365,"NA") -> NA | P5: =IF(M5="EOS",(TODAY()-L5)/365,"NA") -> NA | Q5: N | R5: SIT units | T5: =AJ5+BB5+BS5+CJ5 -> 0 | U5: =AK5+BC5+BT5+CK5 -> 0 | V5: =AL5+BD5+BU5+CL5 -> 0 | W5: =IF(COUNTA(AC5,AU5,BL5,CC5)=0,"",IF(CC5<>"",CC5,IF(BL5<>"",BL5,IF(AU5<>"",AU5,AC5)))) -> Planning | Y5: =IF(AND(X5<>"", AO5<>""),X5-AO5,0) -> 0 | AA5: =IF(AK5+BC5+BT5+CK5-Z5>=0,AK5+BC5+BT5+CK5-Z5,0) -> 0 | AB5: New Test | AC5: Planning | AD5: Driver | AE5: Camera Driver | AJ5: =IF(AK5=0,0,AK5/AQ5/7) -> 0 | AR5: INV introduce new DFC camera, driver has update
B6: C38 AIO_202605_13 | C6: 2026 | D6: May | E6: C38 AIO | F6: Consumer | G6: LOC21 | H6: =IFERROR(VLOOKUP(G6,'C38 NB project list'!F:J,2,0),IFERROR(VLOOKUP(G6, 'C38 AIO project list'!E:I,2,0),"")) -> IdeaCentre AIO 24AKP10 | I6: =IFERROR(VLOOKUP(G6,'C38 NB project list'!F:J,4,0),IFERROR(VLOOKUP(G6, 'C38 AIO project list'!E:I,4,0),"")) -> 45791 | J6: =IF(K6<=TODAY(),"Y","N") -> N | K6: =IFERROR(VLOOKUP(G6,'C38 NB project list'!F:J,5,0),IFERROR(VLOOKUP(G6,'C38 AIO project list'!E:I,5,0),"")) -> 46660 | L6: =IF(ISNUMBER(K6),EDATE(K6,60),"") -> 48487 | M6: =IF(COUNT(I6,K6,L6)=0, "", IF(TODAY()<I6,"NPI",IF(TODAY()<K6,"MP",IF(TODAY()<L6,"EOP","EOS")))) -> MP | N6: =IF(M6="MP",(TODAY()-I6)/365,"NA") -> 1.0575342 | O6: =IF(M6="EOP",(TODAY()-K6)/365,"NA") -> NA | P6: =IF(M6="EOS",(TODAY()-L6)/365,"NA") -> NA | Q6: N | R6: SIT units | T6: =AJ6+BB6+BS6+CJ6 -> 0 | U6: =AK6+BC6+BT6+CK6 -> 0 | V6: =AL6+BD6+BU6+CL6 -> 0 | W6: =IF(COUNTA(AC6,AU6,BL6,CC6)=0,"",IF(CC6<>"",CC6,IF(BL6<>"",BL6,IF(AU6<>"",AU6,AC6)))) -> Planning | Y6: =IF(AND(X6<>"", AO6<>""),X6-AO6,0) -> 0 | AA6: =IF(AK6+BC6+BT6+CK6-Z6>=0,AK6+BC6+BT6+CK6-Z6,0) -> 0 | AB6: New Test | AC6: Planning | AD6: Driver | AE6: Camera Driver | AJ6: =IF(AK6=0,0,AK6/AQ6/7) -> 0 | AR6: INV introduce new DFC camera, driver has update | BB6: =IF(BC6=0,0,BC6/BH6/7) -> 0
B7: C38 AIO_202605_12 | C7: 2026 | D7: May | E7: C38 AIO | F7: Consumer | G7: LOC20 | H7: =IFERROR(VLOOKUP(G7,'C38 NB project list'!F:J,2,0),IFERROR(VLOOKUP(G7, 'C38 AIO project list'!E:I,2,0),"")) -> IdeaCentre AIO 24AKP10 | I7: =IFERROR(VLOOKUP(G7,'C38 NB project list'!F:J,4,0),IFERROR(VLOOKUP(G7, 'C38 AIO project list'!E:I,4,0),"")) -> 45835 | J7: =IF(K7<=TODAY(),"Y","N") -> N | K7: =IFERROR(VLOOKUP(G7,'C38 NB project list'!F:J,5,0),IFERROR(VLOOKUP(G7,'C38 AIO project list'!E:I,5,0),"")) -> 46660 | L7: =IF(ISNUMBER(K7),EDATE(K7,60),"") -> 48487 | M7: =IF(COUNT(I7,K7,L7)=0, "", IF(TODAY()<I7,"NPI",IF(TODAY()<K7,"MP",IF(TODAY()<L7,"EOP","EOS")))) -> MP | N7: =IF(M7="MP",(TODAY()-I7)/365,"NA") -> 0.9369863 | O7: =IF(M7="EOP",(TODAY()-K7)/365,"NA") -> NA | P7: =IF(M7="EOS",(TODAY()-L7)/365,"NA") -> NA | Q7: N | R7: SIT units | T7: =AJ7+BB7+BS7+CJ7 -> 0 | U7: =AK7+BC7+BT7+CK7 -> 0 | V7: =AL7+BD7+BU7+CL7 -> 0 | W7: =IF(COUNTA(AC7,AU7,BL7,CC7)=0,"",IF(CC7<>"",CC7,IF(BL7<>"",BL7,IF(AU7<>"",AU7,AC7)))) -> Planning | Y7: =IF(AND(X7<>"", AO7<>""),X7-AO7,0) -> 0 | AA7: =IF(AK7+BC7+BT7+CK7-Z7>=0,AK7+BC7+BT7+CK7-Z7,0) -> 0 | AB7: New Test | AC7: Planning | AD7: Driver | AE7: Camera Driver | AJ7: =IF(AK7=0,0,AK7/AQ7/7) -> 0 | AR7: INV introduce new DFC camera, driver has update | BB7: =IF(BC7=0,0,BC7/BH7/7) -> 0
B8: C38 AIO_202605_11 | C8: 2026 | D8: May | E8: C38 AIO | F8: Consumer | G8: KOC10 | H8: =IFERROR(VLOOKUP(G8,'C38 NB project list'!F:J,2,0),IFERROR(VLOOKUP(G8, 'C38 AIO project list'!E:I,2,0),"")) -> IdeaCentre AIO 24IRH9 | I8: =IFERROR(VLOOKUP(G8,'C38 NB project list'!F:J,4,0),IFERROR(VLOOKUP(G8, 'C38 AIO project list'!E:I,4,0),"")) -> 45677 | J8: =IF(K8<=TODAY(),"Y","N") -> N | K8: =IFERROR(VLOOKUP(G8,'C38 NB project list'!F:J,5,0),IFERROR(VLOOKUP(G8,'C38 AIO project list'!E:I,5,0),"")) -> 46477 | L8: =IF(ISNUMBER(K8),EDATE(K8,60),"") -> 48304 | M8: =IF(COUNT(I8,K8,L8)=0, "", IF(TODAY()<I8,"NPI",IF(TODAY()<K8,"MP",IF(TODAY()<L8,"EOP","EOS")))) -> MP | N8: =IF(M8="MP",(TODAY()-I8)/365,"NA") -> 1.369863 | O8: =IF(M8="EOP",(TODAY()-K8)/365,"NA") -> NA | P8: =IF(M8="EOS",(TODAY()-L8)/365,"NA") -> NA | Q8: N | R8: SIT units | T8: =AJ8+BB8+BS8+CJ8 -> 0 | U8: =AK8+BC8+BT8+CK8 -> 0 | V8: =AL8+BD8+BU8+CL8 -> 0 | W8: =IF(COUNTA(AC8,AU8,BL8,CC8)=0,"",IF(CC8<>"",CC8,IF(BL8<>"",BL8,IF(AU8<>"",AU8,AC8)))) -> Planning | Y8: =IF(AND(X8<>"", AO8<>""),X8-AO8,0) -> 0 | AA8: =IF(AK8+BC8+BT8+CK8-Z8>=0,AK8+BC8+BT8+CK8-Z8,0) -> 0 | AB8: New Test | AC8: Planning | AD8: Driver | AE8: Camera Driver | AJ8: =IF(AK8=0,0,AK8/AQ8/7) -> 0 | AR8: INV introduce new DFC camera, driver has update | BB8: =IF(BC8=0,0,BC8/BH8/7) -> 0
B9: C38 AIO_202605_10 | C9: 2026 | D9: May | E9: C38 AIO | F9: Consumer | G9: JOC10 | H9: =IFERROR(VLOOKUP(G9,'C38 NB project list'!F:J,2,0),IFERROR(VLOOKUP(G9, 'C38 AIO project list'!E:I,2,0),"")) -> IdeaCentre AIO 24IRH9 | I9: =IFERROR(VLOOKUP(G9,'C38 NB project list'!F:J,4,0),IFERROR(VLOOKUP(G9, 'C38 AIO project list'!E:I,4,0),"")) -> 45303 | J9: =IF(K9<=TODAY(),"Y","N") -> N | K9: =IFERROR(VLOOKUP(G9,'C38 NB project list'!F:J,5,0),IFERROR(VLOOKUP(G9,'C38 AIO project list'!E:I,5,0),"")) -> 46477 | L9: =IF(ISNUMBER(K9),EDATE(K9,60),"") -> 48304 | M9: =IF(COUNT(I9,K9,L9)=0, "", IF(TODAY()<I9,"NPI",IF(TODAY()<K9,"MP",IF(TODAY()<L9,"EOP","EOS")))) -> MP | N9: =IF(M9="MP",(TODAY()-I9)/365,"NA") -> 2.3945205 | O9: =IF(M9="EOP",(TODAY()-K9)/365,"NA") -> NA | P9: =IF(M9="EOS",(TODAY()-L9)/365,"NA") -> NA | Q9: N | R9: SIT units | T9: =AJ9+BB9+BS9+CJ9 -> 0 | U9: =AK9+BC9+BT9+CK9 -> 0 | V9: =AL9+BD9+BU9+CL9 -> 0 | W9: =IF(COUNTA(AC9,AU9,BL9,CC9)=0,"",IF(CC9<>"",CC9,IF(BL9<>"",BL9,IF(AU9<>"",AU9,AC9)))) -> Planning | Y9: =IF(AND(X9<>"", AO9<>""),X9-AO9,0) -> 0 | AA9: =IF(AK9+BC9+BT9+CK9-Z9>=0,AK9+BC9+BT9+CK9-Z9,0) -> 0 | AB9: New Test | AC9: Planning | AD9: Driver | AE9: Camera Driver | AJ9: =IF(AK9=0,0,AK9/AQ9/7) -> 0 | AR9: INV introduce new DFC camera, driver has update | BB9: =IF(BC9=0,0,BC9/BH9/7) -> 0
B10: C38 AIO_202605_09 | C10: 2026 | D10: May | E10: C38 AIO | F10: Consumer | G10: KOC10 | H10: =IFERROR(VLOOKUP(G10,'C38 NB project list'!F:J,2,0),IFERROR(VLOOKUP(G10, 'C38 AIO project list'!E:I,2,0),"")) -> IdeaCentre AIO 24IRH9 | I10: =IFERROR(VLOOKUP(G10,'C38 NB project list'!F:J,4,0),IFERROR(VLOOKUP(G10, 'C38 AIO project list'!E:I,4,0),"")) -> 45677 | J10: =IF(K10<=TODAY(),"Y","N") -> N | K10: =IFERROR(VLOOKUP(G10,'C38 NB project list'!F:J,5,0),IFERROR(VLOOKUP(G10,'C38 AIO project list'!E:I,5,0),"")) -> 46477 | L10: =IF(ISNUMBER(K10),EDATE(K10,60),"") -> 48304 | M10: =IF(COUNT(I10,K10,L10)=0, "", IF(TODAY()<I10,"NPI",IF(TODAY()<K10,"MP",IF(TODAY()<L10,"EOP","EOS")))) -> MP | N10: =IF(M10="MP",(TODAY()-I10)/365,"NA") -> 1.369863 | O10: =IF(M10="EOP",(TODAY()-K10)/365,"NA") -> NA | P10: =IF(M10="EOS",(TODAY()-L10)/365,"NA") -> NA | Q10: N | R10: SIT units | S10: 8 | T10: =AJ10+BB10+BS10+CJ10 -> 2.2142857 | U10: =AK10+BC10+BT10+CK10 -> 62 | V10: =AL10+BD10+BU10+CL10 -> 0 | W10: =IF(COUNTA(AC10,AU10,BL10,CC10)=0,"",IF(CC10<>"",CC10,IF(BL10<>"",BL10,IF(AU10<>"",AU10,AC10)))) -> Pass | Y10: =IF(AND(X10<>"", AO10<>""),X10-AO10,0) -> 0 | Z10: 62 | AA10: =IF(AK10+BC10+BT10+CK10-Z10>=0,AK10+BC10+BT10+CK10-Z10,0) -> 0 | AB10: New Test | AC10: Pass | AD10: BIOS | AE10: BIOS | AF10: O6QKT10A | AG10: OS: 25H2 26200.7171 Driver: v1.0 | AH10: Image build | AJ10: =IF(AK10=0,0,AK10/AQ10/7) -> 2.2142857 | AK10: 62 | AL10: 0 | AM10: Sustain | AN10: Iris_Zhou/Mint_Song/Erin_Pan | AO10: 46150 | AP10: 46155 | AQ10: 4 | AR10: Urgent Release，Update BIOS（disable SAGV) to fix Micron RAM can't boot to OS issue | BB10: =IF(BC10=0,0,BC10/BH10/7) -> 0
B11: C38 AIO_202605_08 | C11: 2026 | D11: May | E11: C38 AIO | F11: Consumer | G11: JOC10 | H11: =IFERROR(VLOOKUP(G11,'C38 NB project list'!F:J,2,0),IFERROR(VLOOKUP(G11, 'C38 AIO project list'!E:I,2,0),"")) -> IdeaCentre AIO 24IRH9 | I11: =IFERROR(VLOOKUP(G11,'C38 NB project list'!F:J,4,0),IFERROR(VLOOKUP(G11, 'C38 AIO project list'!E:I,4,0),"")) -> 45303 | J11: =IF(K11<=TODAY(),"Y","N") -> N | K11: =IFERROR(VLOOKUP(G11,'C38 NB project list'!F:J,5,0),IFERROR(VLOOKUP(G11,'C38 AIO project list'!E:I,5,0),"")) -> 46477 | L11: =IF(ISNUMBER(K11),EDATE(K11,60),"") -> 48304 | M11: =IF(COUNT(I11,K11,L11)=0, "", IF(TODAY()<I11,"NPI",IF(TODAY()<K11,"MP",IF(TODAY()<L11,"EOP","EOS")))) -> MP | N11: =IF(M11="MP",(TODAY()-I11)/365,"NA") -> 2.3945205 | O11: =IF(M11="EOP",(TODAY()-K11)/365,"NA") -> NA | P11: =IF(M11="EOS",(TODAY()-L11)/365,"NA") -> NA | Q11: N | R11: SIT units | S11: 13 | T11: =AJ11+BB11+BS11+CJ11 -> 2.25 | U11: =AK11+BC11+BT11+CK11 -> 63 | V11: =AL11+BD11+BU11+CL11 -> 0 | W11: =IF(COUNTA(AC11,AU11,BL11,CC11)=0,"",IF(CC11<>"",CC11,IF(BL11<>"",BL11,IF(AU11<>"",AU11,AC11)))) -> Fail | Y11: =IF(AND(X11<>"", AO11<>""),X11-AO11,0) -> 0 | Z11: 62 | AA11: =IF(AK11+BC11+BT11+CK11-Z11>=0,AK11+BC11+BT11+CK11-Z11,0) -> 1 | AB11: New Test | AC11: Fail | AD11: BIOS | AE11: BIOS | AF11: O6AKT27A | AG11: OS: 25H2 26200.7171 Driver: v1.0 | AH11: Image build | AJ11: =IF(AK11=0,0,AK11/AQ11/7) -> 2.25 | AK11: 63 | AL11: 0 | AM11: Sustain | AN11: Sustain team:Iris_Zhou/Lulu_Chen/Lom_Ge | AO11: 46150 | AP11: 46155 | AQ11: 4 | AR11: Urgent Release，Update BIOS（disable SAGV) to fix Micron RAM can't boot to OS issue | BB11: =IF(BC11=0,0,BC11/BH11/7) -> 0
B12: C38 AIO_202605_07 | C12: 2026 | D12: May | E12: C38 AIO | F12: Consumer | G12: KOC10 | H12: =IFERROR(VLOOKUP(G12,'C38 NB project list'!F:J,2,0),IFERROR(VLOOKUP(G12, 'C38 AIO project list'!E:I,2,0),"")) -> IdeaCentre AIO 24IRH9 | I12: =IFERROR(VLOOKUP(G12,'C38 NB project list'!F:J,4,0),IFERROR(VLOOKUP(G12, 'C38 AIO project list'!E:I,4,0),"")) -> 45677 | J12: =IF(K12<=TODAY(),"Y","N") -> N | K12: =IFERROR(VLOOKUP(G12,'C38 NB project list'!F:J,5,0),IFERROR(VLOOKUP(G12,'C38 AIO project list'!E:I,5,0),"")) -> 46477 | L12: =IF(ISNUMBER(K12),EDATE(K12,60),"") -> 48304 | M12: =IF(COUNT(I12,K12,L12)=0, "", IF(TODAY()<I12,"NPI",IF(TODAY()<K12,"MP",IF(TODAY()<L12,"EOP","EOS")))) -> MP | N12: =IF(M12="MP",(TODAY()-I12)/365,"NA") -> 1.369863 | O12: =IF(M12="EOP",(TODAY()-K12)/365,"NA") -> NA | P12: =IF(M12="EOS",(TODAY()-L12)/365,"NA") -> NA | Q12: N | R12: SIT units | S12: 9 | T12: =AJ12+BB12+BS12+CJ12 -> 1.2653061 | U12: =AK12+BC12+BT12+CK12 -> 62 | V12: =AL12+BD12+BU12+CL12 -> 0 | W12: =IF(COUNTA(AC12,AU12,BL12,CC12)=0,"",IF(CC12<>"",CC12,IF(BL12<>"",BL12,IF(AU12<>"",AU12,AC12)))) -> Pass | Y12: =IF(AND(X12<>"", AO12<>""),X12-AO12,0) -> 0 | Z12: 62 | AA12: =IF(AK12+BC12+BT12+CK12-Z12>=0,AK12+BC12+BT12+CK12-Z12,0) -> 0 | AB12: New Test | AC12: Pass | AD12: BIOS | AE12: BIOS | AF12: O6QKT11A | AG12: OS: 25H2 26200.7171 Driver: v1.0 | AH12: Image build | AJ12: =IF(AK12=0,0,AK12/AQ12/7) -> 1.2653061 | AK12: 62 | AL12: 0 | AM12: Sustain | AN12: Sustain team:Iris_Zhou/Oliver_Li | AO12: 46160 | AQ12: 7 | AR12: BIOS Security update | BB12: =IF(BC12=0,0,BC12/BH12/7) -> 0
B13: C38 AIO_202605_06 | C13: 2026 | D13: May | E13: C38 AIO | F13: Consumer | G13: JOC10 | H13: =IFERROR(VLOOKUP(G13,'C38 NB project list'!F:J,2,0),IFERROR(VLOOKUP(G13, 'C38 AIO project list'!E:I,2,0),"")) -> IdeaCentre AIO 24IRH9 | I13: =IFERROR(VLOOKUP(G13,'C38 NB project list'!F:J,4,0),IFERROR(VLOOKUP(G13, 'C38 AIO project list'!E:I,4,0),"")) -> 45303 | J13: =IF(K13<=TODAY(),"Y","N") -> N | K13: =IFERROR(VLOOKUP(G13,'C38 NB project list'!F:J,5,0),IFERROR(VLOOKUP(G13,'C38 AIO project list'!E:I,5,0),"")) -> 46477 | L13: =IF(ISNUMBER(K13),EDATE(K13,60),"") -> 48304 | M13: =IF(COUNT(I13,K13,L13)=0, "", IF(TODAY()<I13,"NPI",IF(TODAY()<K13,"MP",IF(TODAY()<L13,"EOP","EOS")))) -> MP | N13: =IF(M13="MP",(TODAY()-I13)/365,"NA") -> 2.3945205 | O13: =IF(M13="EOP",(TODAY()-K13)/365,"NA") -> NA | P13: =IF(M13="EOS",(TODAY()-L13)/365,"NA") -> NA | Q13: N | R13: SIT units | S13: 9 | T13: =AJ13+BB13+BS13+CJ13 -> 1.2857143 | U13: =AK13+BC13+BT13+CK13 -> 63 | V13: =AL13+BD13+BU13+CL13 -> 0 | W13: =IF(COUNTA(AC13,AU13,BL13,CC13)=0,"",IF(CC13<>"",CC13,IF(BL13<>"",BL13,IF(AU13<>"",AU13,AC13)))) -> Fail | Y13: =IF(AND(X13<>"", AO13<>""),X13-AO13,0) -> 0 | Z13: 62 | AA13: =IF(AK13+BC13+BT13+CK13-Z13>=0,AK13+BC13+BT13+CK13-Z13,0) -> 1 | AB13: New Test | AC13: Fail | AD13: BIOS | AE13: BIOS | AF13: O6AKT28A | AG13: OS: 25H2 26200.7171 Driver: v1.0 | AH13: Image build | AJ13: =IF(AK13=0,0,AK13/AQ13/7) -> 1.2857143 | AK13: 63 | AL13: 0 | AM13: Sustain | AN13: Sustain team:Iris_Zhou/Lulu_Chen | AO13: 46160 | AQ13: 7 | AR13: BIOS Security update | BB13: =IF(BC13=0,0,BC13/BH13/7) -> 0
B14: C38 AIO_202605_05 | C14: 2026 | D14: May | E14: C38 AIO | F14: Consumer | G14: LOA70 | H14: =IFERROR(VLOOKUP(G14,'C38 NB project list'!F:J,2,0),IFERROR(VLOOKUP(G14, 'C38 AIO project list'!E:I,2,0),"")) -> Yoga AIO 27IPH11 | I14: =IFERROR(VLOOKUP(G14,'C38 NB project list'!F:J,4,0),IFERROR(VLOOKUP(G14, 'C38 AIO project list'!E:I,4,0),"")) -> 46051 | J14: =IF(K14<=TODAY(),"Y","N") -> N | K14: =IFERROR(VLOOKUP(G14,'C38 NB project list'!F:J,5,0),IFERROR(VLOOKUP(G14,'C38 AIO project list'!E:I,5,0),"")) -> 46417 | L14: =IF(ISNUMBER(K14),EDATE(K14,60),"") -> 48243 | M14: =IF(COUNT(I14,K14,L14)=0, "", IF(TODAY()<I14,"NPI",IF(TODAY()<K14,"MP",IF(TODAY()<L14,"EOP","EOS")))) -> MP | N14: =IF(M14="MP",(TODAY()-I14)/365,"NA") -> 0.34520548 | O14: =IF(M14="EOP",(TODAY()-K14)/365,"NA") -> NA | P14: =IF(M14="EOS",(TODAY()-L14)/365,"NA") -> NA | Q14: N | R14: SIT units | S14: 7 | T14: =AJ14+BB14+BS14+CJ14 -> 1.2085714 | U14: =AK14+BC14+BT14+CK14 -> 84.6 | V14: =AL14+BD14+BU14+CL14 -> 0 | W14: =IF(COUNTA(AC14,AU14,BL14,CC14)=0,"",IF(CC14<>"",CC14,IF(BL14<>"",BL14,IF(AU14<>"",AU14,AC14)))) -> Testing | Y14: =IF(AND(X14<>"", AO14<>""),X14-AO14,0) -> 0 | Z14: 81.6 | AA14: =IF(AK14+BC14+BT14+CK14-Z14>=0,AK14+BC14+BT14+CK14-Z14,0) -> 3 | AB14: New Test | AC14: Testing | AD14: BIOS | AE14: BIOS | AF14: O6VKT1EA | AH14: Image build | AJ14: =IF(AK14=0,0,AK14/AQ14/7) -> 1.2085714 | AK14: 84.6 | AL14: 0 | AM14: Sustain | AN14: Sustain team:Iris_Zhou/Gloria_Gu | AO14: 46161 | AQ14: 10 | AR14: BIOS Security update+ MCU update | BB14: =IF(BC14=0,0,BC14/BH14/7) -> 0
B15: C38 AIO_202605_04 | C15: 2026 | D15: May | E15: C38 AIO | F15: Consumer | G15: LOC75 | H15: =IFERROR(VLOOKUP(G15,'C38 NB project list'!F:J,2,0),IFERROR(VLOOKUP(G15, 'C38 AIO project list'!E:I,2,0),"")) -> IdeaCentre AIO 27IPH11 | I15: =IFERROR(VLOOKUP(G15,'C38 NB project list'!F:J,4,0),IFERROR(VLOOKUP(G15, 'C38 AIO project list'!E:I,4,0),"")) -> 46051 | J15: =IF(K15<=TODAY(),"Y","N") -> N | K15: =IFERROR(VLOOKUP(G15,'C38 NB project list'!F:J,5,0),IFERROR(VLOOKUP(G15,'C38 AIO project list'!E:I,5,0),"")) -> 46417 | L15: =IF(ISNUMBER(K15),EDATE(K15,60),"") -> 48243 | M15: =IF(COUNT(I15,K15,L15)=0, "", IF(TODAY()<I15,"NPI",IF(TODAY()<K15,"MP",IF(TODAY()<L15,"EOP","EOS")))) -> MP | N15: =IF(M15="MP",(TODAY()-I15)/365,"NA") -> 0.34520548 | O15: =IF(M15="EOP",(TODAY()-K15)/365,"NA") -> NA | P15: =IF(M15="EOS",(TODAY()-L15)/365,"NA") -> NA | Q15: N | R15: SIT units | S15: 6 | T15: =AJ15+BB15+BS15+CJ15 -> 1.1942857 | U15: =AK15+BC15+BT15+CK15 -> 83.6 | V15: =AL15+BD15+BU15+CL15 -> 0 | W15: =IF(COUNTA(AC15,AU15,BL15,CC15)=0,"",IF(CC15<>"",CC15,IF(BL15<>"",BL15,IF(AU15<>"",AU15,AC15)))) -> Testing | Y15: =IF(AND(X15<>"", AO15<>""),X15-AO15,0) -> 0 | Z15: 81.6 | AA15: =IF(AK15+BC15+BT15+CK15-Z15>=0,AK15+BC15+BT15+CK15-Z15,0) -> 2 | AB15: New Test | AC15: Testing | AD15: BIOS | AE15: BIOS | AF15: O6WKT1DA | AH15: Image build | AJ15: =IF(AK15=0,0,AK15/AQ15/7) -> 1.1942857 | AK15: 83.6 | AL15: 0 | AM15: Sustain | AN15: Sustain team:Iris_Zhou/Mint_Song | AO15: 46161 | AQ15: 10 | AR15: BIOS Security update+ MCU update | BB15: =IF(BC15=0,0,BC15/BH15/7) -> 0
B16: C38 AIO_202605_03 | C16: 2026 | D16: May | E16: C38 AIO | F16: Consumer | G16: LOA70 | H16: =IFERROR(VLOOKUP(G16,'C38 NB project list'!F:J,2,0),IFERROR(VLOOKUP(G16, 'C38 AIO project list'!E:I,2,0),"")) -> Yoga AIO 27IPH11 | I16: =IFERROR(VLOOKUP(G16,'C38 NB project list'!F:J,4,0),IFERROR(VLOOKUP(G16, 'C38 AIO project list'!E:I,4,0),"")) -> 46051 | J16: =IF(K16<=TODAY(),"Y","N") -> N | K16: =IFERROR(VLOOKUP(G16,'C38 NB project list'!F:J,5,0),IFERROR(VLOOKUP(G16,'C38 AIO project list'!E:I,5,0),"")) -> 46417 | L16: =IF(ISNUMBER(K16),EDATE(K16,60),"") -> 48243 | M16: =IF(COUNT(I16,K16,L16)=0, "", IF(TODAY()<I16,"NPI",IF(TODAY()<K16,"MP",IF(TODAY()<L16,"EOP","EOS")))) -> MP | N16: =IF(M16="MP",(TODAY()-I16)/365,"NA") -> 0.34520548 | O16: =IF(M16="EOP",(TODAY()-K16)/365,"NA") -> NA | P16: =IF(M16="EOS",(TODAY()-L16)/365,"NA") -> NA | Q16: N | R16: SIT units | S16: 2 | T16: =AJ16+BB16+BS16+CJ16 -> 0.86428571 | U16: =AK16+BC16+BT16+CK16 -> 24.2 | V16: =AL16+BD16+BU16+CL16 -> 0 | W16: =IF(COUNTA(AC16,AU16,BL16,CC16)=0,"",IF(CC16<>"",CC16,IF(BL16<>"",BL16,IF(AU16<>"",AU16,AC16)))) -> Pass | Y16: =IF(AND(X16<>"", AO16<>""),X16-AO16,0) -> 0 | Z16: 24.2 | AA16: =IF(AK16+BC16+BT16+CK16-Z16>=0,AK16+BC16+BT16+CK16-Z16,0) -> 0 | AB16: New Test | AC16: Pass | AD16: Driver | AE16: KB Driver | AF16: 3.0.0.1 | AG16: BIOS:O6VKT1DA Driver:V0.24 OS: 26200.7462 | AH16: Image build | AJ16: =IF(AK16=0,0,AK16/AQ16/7) -> 0.86428571 | AK16: 24.2 | AL16: 0 | AM16: NPI | AN16: NPI team:Mary_Zhong | AO16: 46154 | AP16: 46157 | AQ16: 4 | AR16: KB driver update for Qira app | BB16: =IF(BC16=0,0,BC16/BH16/7) -> 0
B17: C38 AIO_202605_02 | C17: 2026 | D17: May | E17: C38 AIO | F17: Consumer | G17: LOC75 | H17: =IFERROR(VLOOKUP(G17,'C38 NB project list'!F:J,2,0),IFERROR(VLOOKUP(G17, 'C38 AIO project list'!E:I,2,0),"")) -> IdeaCentre AIO 27IPH11 | I17: =IFERROR(VLOOKUP(G17,'C38 NB project list'!F:J,4,0),IFERROR(VLOOKUP(G17, 'C38 AIO project list'!E:I,4,0),"")) -> 46051 | J17: =IF(K17<=TODAY(),"Y","N") -> N | K17: =IFERROR(VLOOKUP(G17,'C38 NB project list'!F:J,5,0),IFERROR(VLOOKUP(G17,'C38 AIO project list'!E:I,5,0),"")) -> 46417 | L17: =IF(ISNUMBER(K17),EDATE(K17,60),"") -> 48243 | M17: =IF(COUNT(I17,K17,L17)=0, "", IF(TODAY()<I17,"NPI",IF(TODAY()<K17,"MP",IF(TODAY()<L17,"EOP","EOS")))) -> MP | N17: =IF(M17="MP",(TODAY()-I17)/365,"NA") -> 0.34520548 | O17: =IF(M17="EOP",(TODAY()-K17)/365,"NA") -> NA | P17: =IF(M17="EOS",(TODAY()-L17)/365,"NA") -> NA | Q17: N | R17: SIT units | S17: 2 | T17: =AJ17+BB17+BS17+CJ17 -> 1.7285714 | U17: =AK17+BC17+BT17+CK17 -> 48.4 | V17: =AL17+BD17+BU17+CL17 -> 0 | W17: =IF(COUNTA(AC17,AU17,BL17,CC17)=0,"",IF(CC17<>"",CC17,IF(BL17<>"",BL17,IF(AU17<>"",AU17,AC17)))) -> Pass | Y17: =IF(AND(X17<>"", AO17<>""),X17-AO17,0) -> 0 | Z17: 24.2 | AA17: =IF(AK17+BC17+BT17+CK17-Z17>=0,AK17+BC17+BT17+CK17-Z17,0) -> 24.2 | AB17: New Test | AC17: Fail | AD17: Driver | AE17: KB Driver | AF17: 2.0.2.02241 | AG17: BIOS:O6WKT1CA Driver:V0.22 OS: 26200.7462 | AH17: Image build | AJ17: =IF(AK17=0,0,AK17/AQ17/7) -> 0.86428571 | AK17: 24.2 | AL17: 0 | AM17: Sustain | AN17: Sustain team:Iris_Zhou/Helen_Meng/Wendy_Qiu | AO17: 46154 | AP17: 46157 | AQ17: 4 | AR17: KB driver update for Qira app | AT17: Regression1 | AU17: Pass | AV17: Driver | AW17: KB Driver | AX17: 2.0.3.03311 | AY17: BIOS:O6WKT1CA Driver:V0.23 OS: 26200.7462 | AZ17: Image build | BB17: =IF(BC17=0,0,BC17/BH17/7) -> 0.86428571 | BC17: 24.2 | BD17: 0 | BE17: Sustain team:Iris_Zhou | BF17: 46160 | BH17: 4 | BI17: Fn+ESC key cannot switch issue for Qira preload test
B18: C38 AIO_202605_01 | C18: 2026 | D18: May | E18: C38 AIO | F18: Consumer | G18: LOC75 | H18: =IFERROR(VLOOKUP(G18,'C38 NB project list'!F:J,2,0),IFERROR(VLOOKUP(G18, 'C38 AIO project list'!E:I,2,0),"")) -> IdeaCentre AIO 27IPH11 | I18: =IFERROR(VLOOKUP(G18,'C38 NB project list'!F:J,4,0),IFERROR(VLOOKUP(G18, 'C38 AIO project list'!E:I,4,0),"")) -> 46051 | J18: =IF(K18<=TODAY(),"Y","N") -> N | K18: =IFERROR(VLOOKUP(G18,'C38 NB project list'!F:J,5,0),IFERROR(VLOOKUP(G18,'C38 AIO project list'!E:I,5,0),"")) -> 46417 | L18: =IF(ISNUMBER(K18),EDATE(K18,60),"") -> 48243 | M18: =IF(COUNT(I18,K18,L18)=0, "", IF(TODAY()<I18,"NPI",IF(TODAY()<K18,"MP",IF(TODAY()<L18,"EOP","EOS")))) -> MP | N18: =IF(M18="MP",(TODAY()-I18)/365,"NA") -> 0.34520548 | O18: =IF(M18="EOP",(TODAY()-K18)/365,"NA") -> NA | P18: =IF(M18="EOS",(TODAY()-L18)/365,"NA") -> NA | Q18: N | R18: SIT units | S18: 2 | T18: =AJ18+BB18+BS18+CJ18 -> 0.86428571 | U18: =AK18+BC18+BT18+CK18 -> 24.2 | V18: =AL18+BD18+BU18+CL18 -> 0 | W18: =IF(COUNTA(AC18,AU18,BL18,CC18)=0,"",IF(CC18<>"",CC18,IF(BL18<>"",BL18,IF(AU18<>"",AU18,AC18)))) -> Pass | Y18: =IF(AND(X18<>"", AO18<>""),X18-AO18,0) -> 0 | Z18: 24.2 | AA18: =IF(AK18+BC18+BT18+CK18-Z18>=0,AK18+BC18+BT18+CK18-Z18,0) -> 0 | AB18: New Test | AC18: Pass | AD18: Driver | AE18: KB Driver | AF18: 1.0.0.11 | AG18: BIOS:O6WKT1CA Driver:V0.22 OS: 26200.7462 | AH18: Image build | AJ18: =IF(AK18=0,0,AK18/AQ18/7) -> 0.86428571 | AK18: 24.2 | AL18: 0 | AM18: Sustain | AN18: Sustain team:Iris_Zhou/Helen_Meng/Wendy_Qiu | AO18: 46154 | AP18: 46157 | AQ18: 4 | AR18: KB driver update for Qira app | BB18: =IF(BC18=0,0,BC18/BH18/7) -> 0
B19: C38 AIO_202604_06 | C19: 2026 | D19: Apr | E19: C38 AIO | F19: Consumer | G19: KOA71 | H19: =IFERROR(VLOOKUP(G19,'C38 NB project list'!F:J,2,0),IFERROR(VLOOKUP(G19, 'C38 AIO project list'!E:I,2,0),"")) -> Yoga AIO 27IAH10 | I19: =IFERROR(VLOOKUP(G19,'C38 NB project list'!F:J,4,0),IFERROR(VLOOKUP(G19, 'C38 AIO project list'!E:I,4,0),"")) -> 45733 | J19: =IF(K19<=TODAY(),"Y","N") -> N | K19: =IFERROR(VLOOKUP(G19,'C38 NB project list'!F:J,5,0),IFERROR(VLOOKUP(G19,'C38 AIO project list'!E:I,5,0),"")) -> 46387 | L19: =IF(ISNUMBER(K19),EDATE(K19,60),"") -> 48213 | M19: =IF(COUNT(I19,K19,L19)=0, "", IF(TODAY()<I19,"NPI",IF(TODAY()<K19,"MP",IF(TODAY()<L19,"EOP","EOS")))) -> MP | N19: =IF(M19="MP",(TODAY()-I19)/365,"NA") -> 1.2164384 | O19: =IF(M19="EOP",(TODAY()-K19)/365,"NA") -> NA | P19: =IF(M19="EOS",(TODAY()-L19)/365,"NA") -> NA | Q19: N | R19: SIT units | S19: 5 | T19: =AJ19+BB19+BS19+CJ19 -> 1.2442857 | U19: =AK19+BC19+BT19+CK19 -> 87.1 | V19: =AL19+BD19+BU19+CL19 -> 0 | W19: =IF(COUNTA(AC19,AU19,BL19,CC19)=0,"",IF(CC19<>"",CC19,IF(BL19<>"",BL19,IF(AU19<>"",AU19,AC19)))) -> Conditional Pass | Y19: =IF(AND(X19<>"", AO19<>""),X19-AO19,0) -> 0 | Z19: 85.1 | AA19: =IF(AK19+BC19+BT19+CK19-Z19>=0,AK19+BC19+BT19+CK19-Z19,0) -> 2 | AB19: New Test | AC19: Conditional Pass | AD19: BIOS | AE19: BIOS | AF19: O6PKT1EA | AG19: OS: 25H2 26200.7171 Driver: v1.0 | AH19: Image build | AJ19: =IF(AK19=0,0,AK19/AQ19/7) -> 1.2442857 | AK19: 87.1 | AL19: 0 | AM19: Sustain | AN19: Sustain team:Iris_Zhou/Gloria_Gu | AO19: 46136 | AP19: 46153 | AQ19: 10 | AR19: MCU update 0x11F | BB19: =IF(BC19=0,0,BC19/BH19/7) -> 0
B20: C38 AIO_202604_05 | C20: 2026 | D20: Apr | E20: C38 AIO | F20: SMB | G20: LOY30 | H20: =IFERROR(VLOOKUP(G20,'C38 NB project list'!F:J,2,0),IFERROR(VLOOKUP(G20, 'C38 AIO project list'!E:I,2,0),"")) -> ThinkCentre neo 50a 24 Gen 6 LNL | I20: =IFERROR(VLOOKUP(G20,'C38 NB project list'!F:J,4,0),IFERROR(VLOOKUP(G20, 'C38 AIO project list'!E:I,4,0),"")) -> 46052 | J20: =IF(K20<=TODAY(),"Y","N") -> N | K20: =IFERROR(VLOOKUP(G20,'C38 NB project list'!F:J,5,0),IFERROR(VLOOKUP(G20,'C38 AIO project list'!E:I,5,0),"")) -> 46420 | L20: =IF(ISNUMBER(K20),EDATE(K20,60),"") -> 48246 | M20: =IF(COUNT(I20,K20,L20)=0, "", IF(TODAY()<I20,"NPI",IF(TODAY()<K20,"MP",IF(TODAY()<L20,"EOP","EOS")))) -> MP | N20: =IF(M20="MP",(TODAY()-I20)/365,"NA") -> 0.34246575 | O20: =IF(M20="EOP",(TODAY()-K20)/365,"NA") -> NA | P20: =IF(M20="EOS",(TODAY()-L20)/365,"NA") -> NA | Q20: N | R20: SIT units | S20: 2 | T20: =AJ20+BB20+BS20+CJ20 -> 1.125 | U20: =AK20+BC20+BT20+CK20 -> 31.5 | V20: =AL20+BD20+BU20+CL20 -> 14.6 | W20: =IF(COUNTA(AC20,AU20,BL20,CC20)=0,"",IF(CC20<>"",CC20,IF(BL20<>"",BL20,IF(AU20<>"",AU20,AC20)))) -> Conditional Pass | Y20: =IF(AND(X20<>"", AO20<>""),X20-AO20,0) -> 0 | Z20: 30 | AA20: =IF(AK20+BC20+BT20+CK20-Z20>=0,AK20+BC20+BT20+CK20-Z20,0) -> 1.5 | AB20: New Test | AC20: Conditional Pass | AD20: APP | AE20: Tianxi | AF20: 3.5.3.2131d | AG20: BIOS: O75KT06A OS: 26200.7462 Driver: v1.0 | AH20: Image build | AJ20: =IF(AK20=0,0,AK20/AQ20/7) -> 1.125 | AK20: 31.5 | AL20: 14.6 | AM20: NPI | AN20: NPI Team: Bella_Guo | AO20: 46122 | AP20: 46127 | AQ20: 4 | AR20: New introduce Tianxi APP | BB20: =IF(BC20=0,0,BC20/BH20/7) -> 0 | CJ20: =IF(CK20=0,0,CK20/CP20/7) -> 0
B21: C38 AIO_202604_04 | C21: 2026 | D21: Apr | E21: C38 AIO | F21: SMB | G21: LOY21 | H21: =IFERROR(VLOOKUP(G21,'C38 NB project list'!F:J,2,0),IFERROR(VLOOKUP(G21, 'C38 AIO project list'!E:I,2,0),"")) -> ThinkCentre neo 55a 24 Gen 6 | I21: =IFERROR(VLOOKUP(G21,'C38 NB project list'!F:J,4,0),IFERROR(VLOOKUP(G21, 'C38 AIO project list'!E:I,4,0),"")) -> 45807 | J21: =IF(K21<=TODAY(),"Y","N") -> N | K21: =IFERROR(VLOOKUP(G21,'C38 NB project list'!F:J,5,0),IFERROR(VLOOKUP(G21,'C38 AIO project list'!E:I,5,0),"")) -> 46660 | L21: =IF(ISNUMBER(K21),EDATE(K21,60),"") -> 48487 | M21: =IF(COUNT(I21,K21,L21)=0, "", IF(TODAY()<I21,"NPI",IF(TODAY()<K21,"MP",IF(TODAY()<L21,"EOP","EOS")))) -> MP | N21: =IF(M21="MP",(TODAY()-I21)/365,"NA") -> 1.0136986 | O21: =IF(M21="EOP",(TODAY()-K21)/365,"NA") -> NA | P21: =IF(M21="EOS",(TODAY()-L21)/365,"NA") -> NA | Q21: N | R21: SIT units | S21: 2 | T21: =AJ21+BB21+BS21+CJ21 -> 1.125 | U21: =AK21+BC21+BT21+CK21 -> 31.5 | V21: =AL21+BD21+BU21+CL21 -> 14.6 | W21: =IF(COUNTA(AC21,AU21,BL21,CC21)=0,"",IF(CC21<>"",CC21,IF(BL21<>"",BL21,IF(AU21<>"",AU21,AC21)))) -> Conditional Pass | Y21: =IF(AND(X21<>"", AO21<>""),X21-AO21,0) -> 0 | Z21: 30 | AA21: =IF(AK21+BC21+BT21+CK21-Z21>=0,AK21+BC21+BT21+CK21-Z21,0) -> 1.5 | AB21: New Test | AC21: Conditional Pass | AD21: APP | AE21: Tianxi | AF21: 3.5.3.2131d | AG21: BIOS: O6TKT0EA OS: 26200.8037 Driver: v1.0 | AH21: Image build | AJ21: =IF(AK21=0,0,AK21/AQ21/7) -> 1.125 | AK21: 31.5 | AL21: 14.6 | AM21: NPI | AN21: NPI Team: Bella_Guo | AO21: 46128 | AP21: 46133 | AQ21: 4 | AR21: New introduce Tianxi APP | BB21: =IF(BC21=0,0,BC21/BH21/7) -> 0
B22: C38 AIO_202604_03 | C22: 2026 | D22: Apr | E22: C38 AIO | F22: Consumer | G22: LOA70 | H22: =IFERROR(VLOOKUP(G22,'C38 NB project list'!F:J,2,0),IFERROR(VLOOKUP(G22, 'C38 AIO project list'!E:I,2,0),"")) -> Yoga AIO 27IPH11 | I22: =IFERROR(VLOOKUP(G22,'C38 NB project list'!F:J,4,0),IFERROR(VLOOKUP(G22, 'C38 AIO project list'!E:I,4,0),"")) -> 46051 | J22: =IF(K22<=TODAY(),"Y","N") -> N | K22: =IFERROR(VLOOKUP(G22,'C38 NB project list'!F:J,5,0),IFERROR(VLOOKUP(G22,'C38 AIO project list'!E:I,5,0),"")) -> 46417 | L22: =IF(ISNUMBER(K22),EDATE(K22,60),"") -> 48243 | M22: =IF(COUNT(I22,K22,L22)=0, "", IF(TODAY()<I22,"NPI",IF(TODAY()<K22,"MP",IF(TODAY()<L22,"EOP","EOS")))) -> MP | N22: =IF(M22="MP",(TODAY()-I22)/365,"NA") -> 0.34520548 | O22: =IF(M22="EOP",(TODAY()-K22)/365,"NA") -> NA | P22: =IF(M22="EOS",(TODAY()-L22)/365,"NA") -> NA | Q22: N | R22: SIT units | S22: 2 | T22: =AJ22+BB22+BS22+CJ22 -> 2.1142857 | U22: =AK22+BC22+BT22+CK22 -> 64 | V22: =AL22+BD22+BU22+CL22 -> 0 | W22: =IF(COUNTA(AC22,AU22,BL22,CC22)=0,"",IF(CC22<>"",CC22,IF(BL22<>"",BL22,IF(AU22<>"",AU22,AC22)))) -> Testing | Y22: =IF(AND(X22<>"", AO22<>""),X22-AO22,0) -> 0 | Z22: 40 | AA22: =IF(AK22+BC22+BT22+CK22-Z22>=0,AK22+BC22+BT22+CK22-Z22,0) -> 24 | AB22: New Test | AC22: Fail | AD22: APP | AE22: Qira | AF22: 1.0.0.0306 | AG22: BIOS: O6VKT1DA OS: 26200.7462 Driver: v1.0 | AH22: Image build | AJ22: =IF(AK22=0,0,AK22/AQ22/7) -> 1.4285714 | AK22: 40 | AL22: 0 | AM22: NPI | AN22: NPI Team: Bella_Guo&Dinna_li | AO22: 46129 | AP22: 46136 | AQ22: 4 | AR22: New introduce Qira APP | AT22: Regression1 | AU22: Testing | AV22: APP | AW22: Qira | AX22: V1.1.0.0509 | AY22: BIOS: O6VKT1DA OS: 26200.7462 Driver: v0.24 | AZ22: Image build | BB22: =IF(BC22=0,0,BC22/BH22/7) -> 0.68571429 | BC22: 24 | BD22: 0 | BE22: NPI Team: Bella_Guo | BF22: 46154 | BH22: 5 | BI22: 1.Update Qira test version to V1.1.0.0509 2. Update KB driver to support Qira
B23: C38 AIO_202604_02 | C23: 2026 | D23: Apr | E23: C38 AIO | F23: Consumer | G23: LOC75 | H23: =IFERROR(VLOOKUP(G23,'C38 NB project list'!F:J,2,0),IFERROR(VLOOKUP(G23, 'C38 AIO project list'!E:I,2,0),"")) -> IdeaCentre AIO 27IPH11 | I23: =IFERROR(VLOOKUP(G23,'C38 NB project list'!F:J,4,0),IFERROR(VLOOKUP(G23, 'C38 AIO project list'!E:I,4,0),"")) -> 46051 | J23: =IF(K23<=TODAY(),"Y","N") -> N | K23: =IFERROR(VLOOKUP(G23,'C38 NB project list'!F:J,5,0),IFERROR(VLOOKUP(G23,'C38 AIO project list'!E:I,5,0),"")) -> 46417 | L23: =IF(ISNUMBER(K23),EDATE(K23,60),"") -> 48243 | M23: =IF(COUNT(I23,K23,L23)=0, "", IF(TODAY()<I23,"NPI",IF(TODAY()<K23,"MP",IF(TODAY()<L23,"EOP","EOS")))) -> MP | N23: =IF(M23="MP",(TODAY()-I23)/365,"NA") -> 0.34520548 | O23: =IF(M23="EOP",(TODAY()-K23)/365,"NA") -> NA | P23: =IF(M23="EOS",(TODAY()-L23)/365,"NA") -> NA | Q23: N | R23: SIT units | S23: 3 | T23: =AJ23+BB23+BS23+CJ23 -> 1.8166667 | U23: =AK23+BC23+BT23+CK23 -> 119 | V23: =AL23+BD23+BU23+CL23 -> 0 | W23: =IF(COUNTA(AC23,AU23,BL23,CC23)=0,"",IF(CC23<>"",CC23,IF(BL23<>"",BL23,IF(AU23<>"",AU23,AC23)))) -> Testing | Y23: =IF(AND(X23<>"", AO23<>""),X23-AO23,0) -> 0 | Z23: 95 | AA23: =IF(AK23+BC23+BT23+CK23-Z23>=0,AK23+BC23+BT23+CK23-Z23,0) -> 24 | AB23: New Test | AC23: Fail | AD23: APP | AE23: Qira | AF23: 1.0.0.0306 | AG23: BIOS: O6WKT1CA OS: 25H2 26200.7462 Driver: v1.0 | AH23: Image build | AJ23: =IF(AK23=0,0,AK23/AQ23/7) -> 1.1309524 | AK23: 95 | AL23: 0 | AM23: NPI | AN23: NPI Team: Bella_Guo&Dinna_li | AO23: 46113 | AP23: 46129 | AQ23: 12 | AR23: New introduce Qira APP | AT23: Regression1 | AU23: Testing | AV23: APP | AW23: Qira | AX23: V1.1.0.0509 | AY23: BIOS: O6WKT1CA OS: 25H2 26200.7462 Driver: v0.22 | AZ23: Image build | BB23: =IF(BC23=0,0,BC23/BH23/7) -> 0.68571429 | BC23: 24 | BD23: 0 | BE23: NPI Team: Bella_Guo | BF23: 46154 | BH23: 5 | BI23: 1.Update Qira test version to V1.1.0.0509 2. Update KB driver to support Qira
B24: C38 AIO_202604_01 | C24: 2026 | D24: Apr | E24: C38 AIO | F24: Consumer | G24: LOC22 | H24: =IFERROR(VLOOKUP(G24,'C38 NB project list'!F:J,2,0),IFERROR(VLOOKUP(G24, 'C38 AIO project list'!E:I,2,0),"")) -> IdeaCentre AIO 24AKP10 | I24: =IFERROR(VLOOKUP(G24,'C38 NB project list'!F:J,4,0),IFERROR(VLOOKUP(G24, 'C38 AIO project list'!E:I,4,0),"")) -> 45835 | J24: =IF(K24<=TODAY(),"Y","N") -> N | K24: =IFERROR(VLOOKUP(G24,'C38 NB project list'!F:J,5,0),IFERROR(VLOOKUP(G24,'C38 AIO project list'!E:I,5,0),"")) -> 46660 | L24: =IF(ISNUMBER(K24),EDATE(K24,60),"") -> 48487 | M24: =IF(COUNT(I24,K24,L24)=0, "", IF(TODAY()<I24,"NPI",IF(TODAY()<K24,"MP",IF(TODAY()<L24,"EOP","EOS")))) -> MP | N24: =IF(M24="MP",(TODAY()-I24)/365,"NA") -> 0.9369863 | O24: =IF(M24="EOP",(TODAY()-K24)/365,"NA") -> NA | P24: =IF(M24="EOS",(TODAY()-L24)/365,"NA") -> NA | Q24: N | R24: SIT units | S24: 6 | T24: =AJ24+BB24+BS24+CJ24 -> 2.4464286 | U24: =AK24+BC24+BT24+CK24 -> 68.5 | V24: =AL24+BD24+BU24+CL24 -> 0 | W24: =IF(COUNTA(AC24,AU24,BL24,CC24)=0,"",IF(CC24<>"",CC24,IF(BL24<>"",BL24,IF(AU24<>"",AU24,AC24)))) -> Conditional Pass | Y24: =IF(AND(X24<>"", AO24<>""),X24-AO24,0) -> 0 | Z24: 65.5 | AA24: =IF(AK24+BC24+BT24+CK24-Z24>=0,AK24+BC24+BT24+CK24-Z24,0) -> 3 | AB24: New Test | AC24: Conditional Pass | AD24: BIOS | AE24: BIOS | AF24: O6XKT16A | AG24: OS: 25H2 26200.6901 Driver: v1.1 | AH24: Image build | AI24: Click link | AJ24: =IF(AK24=0,0,AK24/AQ24/7) -> 2.4464286 | AK24: 68.5 | AL24: 0 | AM24: Sustain | AN24: Sustain team: Gloria_Gu/Vivill_Zou | AO24: 46115 | AP24: 46121 | AQ24: 4 | AR24: 1.Y25Q2 LEN-199280 INSYDE-SA-2025005 Arbitrary Code Execution Vulnerabilities 2.Y25Q3 LEN-198949 EDKII SMM IDT privilege escalation vulnerability(AMD only） 3.Y25Q4 LEN-208121 INSYDE-SA-2025010 Buffer Overflow in H2OFFT Tool (H2O-0922-2501) 4.Update UEFIDaig to 04.43.00 | AS24: Introduce this BIOS to fix LOC22 MFG SSD lost issue | BB24: =IF(BC24=0,0,BC24/BH24/7) -> 0
B25: C38 AIO_202603_01 | C25: 2026 | D25: Apr | E25: C38 AIO | F25: Consumer | G25: LOC21 | H25: =IFERROR(VLOOKUP(G25,'C38 NB project list'!F:J,2,0),IFERROR(VLOOKUP(G25, 'C38 AIO project list'!E:I,2,0),"")) -> IdeaCentre AIO 24AKP10 | I25: =IFERROR(VLOOKUP(G25,'C38 NB project list'!F:J,4,0),IFERROR(VLOOKUP(G25, 'C38 AIO project list'!E:I,4,0),"")) -> 45791 | J25: =IF(K25<=TODAY(),"Y","N") -> N | K25: =IFERROR(VLOOKUP(G25,'C38 NB project list'!F:J,5,0),IFERROR(VLOOKUP(G25,'C38 AIO project list'!E:I,5,0),"")) -> 46660 | L25: =IF(ISNUMBER(K25),EDATE(K25,60),"") -> 48487 | M25: =IF(COUNT(I25,K25,L25)=0, "", IF(TODAY()<I25,"NPI",IF(TODAY()<K25,"MP",IF(TODAY()<L25,"EOP","EOS")))) -> MP | N25: =IF(M25="MP",(TODAY()-I25)/365,"NA") -> 1.0575342 | O25: =IF(M25="EOP",(TODAY()-K25)/365,"NA") -> NA | P25: =IF(M25="EOS",(TODAY()-L25)/365,"NA") -> NA | Q25: N | R25: SIT units | S25: 3 | T25: =AJ25+BB25+BS25+CJ25 -> 1.4171429 | U25: =AK25+BC25+BT25+CK25 -> 49.6 | V25: =AL25+BD25+BU25+CL25 -> 0 | W25: =IF(COUNTA(AC25,AU25,BL25,CC25)=0,"",IF(CC25<>"",CC25,IF(BL25<>"",BL25,IF(AU25<>"",AU25,AC25)))) -> Conditional Pass | Y25: =IF(AND(X25<>"", AO25<>""),X25-AO25,0) -> 0 | Z25: 44.6 | AA25: =IF(AK25+BC25+BT25+CK25-Z25>=0,AK25+BC25+BT25+CK25-Z25,0) -> 5 | AB25: New Test | AC25: Conditional Pass | AD25: APP | AE25: Tianxi | AF25: 3.5.3.2131c 3.5.3.2131d | AG25: BIOS: O6TKT0EA OS: 26200.8037 Driver: v1.0 | AH25: Image build | AJ25: =IF(AK25=0,0,AK25/AQ25/7) -> 1.4171429 | AK25: 49.6 | AL25: 0 | AM25: NPI | AN25: NPI Team: Bella_Guo Sustain team: Iris_zhou/Lulu_Chen | AO25: 46111 | AP25: 46126 | AQ25: 5 | AR25: New introduce Tianxi APP | BB25: =IF(BC25=0,0,BC25/BH25/7) -> 0 | BS25: =IF(BT25=0,0,BT25/BY25/7) -> 0
B26: C38 AIO_202603_02 | C26: 2026 | D26: Apr | E26: C38 AIO | F26: Consumer | G26: LOC20 | H26: =IFERROR(VLOOKUP(G26,'C38 NB project list'!F:J,2,0),IFERROR(VLOOKUP(G26, 'C38 AIO project list'!E:I,2,0),"")) -> IdeaCentre AIO 24AKP10 | I26: =IFERROR(VLOOKUP(G26,'C38 NB project list'!F:J,4,0),IFERROR(VLOOKUP(G26, 'C38 AIO project list'!E:I,4,0),"")) -> 45835 | J26: =IF(K26<=TODAY(),"Y","N") -> N | K26: =IFERROR(VLOOKUP(G26,'C38 NB project list'!F:J,5,0),IFERROR(VLOOKUP(G26,'C38 AIO project list'!E:I,5,0),"")) -> 46660 | L26: =IF(ISNUMBER(K26),EDATE(K26,60),"") -> 48487 | M26: =IF(COUNT(I26,K26,L26)=0, "", IF(TODAY()<I26,"NPI",IF(TODAY()<K26,"MP",IF(TODAY()<L26,"EOP","EOS")))) -> MP | N26: =IF(M26="MP",(TODAY()-I26)/365,"NA") -> 0.9369863 | O26: =IF(M26="EOP",(TODAY()-K26)/365,"NA") -> NA | P26: =IF(M26="EOS",(TODAY()-L26)/365,"NA") -> NA | Q26: N | R26: SIT units | S26: 2 | T26: =AJ26+BB26+BS26+CJ26 -> 1.4314286 | U26: =AK26+BC26+BT26+CK26 -> 50.1 | V26: =AL26+BD26+BU26+CL26 -> 0 | W26: =IF(COUNTA(AC26,AU26,BL26,CC26)=0,"",IF(CC26<>"",CC26,IF(BL26<>"",BL26,IF(AU26<>"",AU26,AC26)))) -> Conditional Pass | Y26: =IF(AND(X26<>"", AO26<>""),X26-AO26,0) -> 0 | Z26: 44.6 | AA26: =IF(AK26+BC26+BT26+CK26-Z26>=0,AK26+BC26+BT26+CK26-Z26,0) -> 5.5 | AB26: New Test | AC26: Conditional Pass | AD26: APP | AE26: Tianxi | AF26: 3.5.3.2131c 3.5.3.2131d | AG26: BIOS: O6SKT13A OS: 26200.6901 Driver: v1.0 | AH26: Image build | AJ26: =IF(AK26=0,0,AK26/AQ26/7) -> 1.4314286 | AK26: 50.1 | AL26: 0 | AM26: NPI | AN26: NPI Team: Bella_Guo Sustain team:Iris_zhou/ Molly_Yuan | AO26: 46111 | AP26: 46126 | AQ26: 5 | AR26: New introduce Tianxi APP | BB26: =IF(BC26=0,0,BC26/BH26/7) -> 0 | BS26: =IF(BT26=0,0,BT26/BY26/7) -> 0
B27: C38 AIO_202603_03 | C27: 2026 | D27: Apr | E27: C38 AIO | F27: Consumer | G27: LOC30 | H27: =IFERROR(VLOOKUP(G27,'C38 NB project list'!F:J,2,0),IFERROR(VLOOKUP(G27, 'C38 AIO project list'!E:I,2,0),"")) -> IdeaCentre AIO 24ILL11 | I27: =IFERROR(VLOOKUP(G27,'C38 NB project list'!F:J,4,0),IFERROR(VLOOKUP(G27, 'C38 AIO project list'!E:I,4,0),"")) -> 46052 | J27: =IF(K27<=TODAY(),"Y","N") -> N | K27: =IFERROR(VLOOKUP(G27,'C38 NB project list'!F:J,5,0),IFERROR(VLOOKUP(G27,'C38 AIO project list'!E:I,5,0),"")) -> 46420 | L27: =IF(ISNUMBER(K27),EDATE(K27,60),"") -> 48246 | M27: =IF(COUNT(I27,K27,L27)=0, "", IF(TODAY()<I27,"NPI",IF(TODAY()<K27,"MP",IF(TODAY()<L27,"EOP","EOS")))) -> MP | N27: =IF(M27="MP",(TODAY()-I27)/365,"NA") -> 0.34246575 | O27: =IF(M27="EOP",(TODAY()-K27)/365,"NA") -> NA | P27: =IF(M27="EOS",(TODAY()-L27)/365,"NA") -> NA | Q27: N | R27: SIT units | S27: 3 | T27: =AJ27+BB27+BS27+CJ27 -> 2.5457143 | U27: =AK27+BC27+BT27+CK27 -> 81.6 | V27: =AL27+BD27+BU27+CL27 -> 0 | W27: =IF(COUNTA(AC27,AU27,BL27,CC27)=0,"",IF(CC27<>"",CC27,IF(BL27<>"",BL27,IF(AU27<>"",AU27,AC27)))) -> Pass | Y27: =IF(AND(X27<>"", AO27<>""),X27-AO27,0) -> 0 | Z27: 44.6 | AA27: =IF(AK27+BC27+BT27+CK27-Z27>=0,AK27+BC27+BT27+CK27-Z27,0) -> 37 | AB27: New Test | AC27: Fail | AD27: APP | AE27: Tianxi | AF27: 3.5.3.2131b | AG27: BIOS: O75KT06A OS: 26200.7462 Driver: v1.0 | AH27: Image build | AJ27: =IF(AK27=0,0,AK27/AQ27/7) -> 1.4742857 | AK27: 51.6 | AL27: 0 | AM27: NPI | AN27: NPI Team: Bella_Guo Sustain team: Iris_zhou/Molly_Yuan | AO27: 46098 | AP27: 46120 | AQ27: 5 | AR27: New introduce Tianxi APP | AT27: Regression1 | AU27: Pass | AV27: APP | AW27: 天禧 | AX27: 3.5.3.2131c | AZ27: Image build | BB27: =IF(BC27=0,0,BC27/BH27/7) -> 1.0714286 | BC27: 30 | BD27: 0 | BE27: NPI team: Bella_Guo | BF27: 46105 | BG27: 46108 | BH27: 4 | BI27: As Lenovo's request to do regression test with new tianxi app v3.5.3.2131c | BS27: =IF(BT27=0,0,BT27/BY27/7) -> 0
B28: C38 AIO_202603_04 | C28: 2026 | D28: Apr | E28: C38 AIO | F28: Consumer | G28: LOC75 | H28: =IFERROR(VLOOKUP(G28,'C38 NB project list'!F:J,2,0),IFERROR(VLOOKUP(G28, 'C38 AIO project list'!E:I,2,0),"")) -> IdeaCentre AIO 27IPH11 | I28: =IFERROR(VLOOKUP(G28,'C38 NB project list'!F:J,4,0),IFERROR(VLOOKUP(G28, 'C38 AIO project list'!E:I,4,0),"")) -> 46051 | J28: =IF(K28<=TODAY(),"Y","N") -> N | K28: =IFERROR(VLOOKUP(G28,'C38 NB project list'!F:J,5,0),IFERROR(VLOOKUP(G28,'C38 AIO project list'!E:I,5,0),"")) -> 46417 | L28: =IF(ISNUMBER(K28),EDATE(K28,60),"") -> 48243 | M28: =IF(COUNT(I28,K28,L28)=0, "", IF(TODAY()<I28,"NPI",IF(TODAY()<K28,"MP",IF(TODAY()<L28,"EOP","EOS")))) -> MP | N28: =IF(M28="MP",(TODAY()-I28)/365,"NA") -> 0.34520548 | O28: =IF(M28="EOP",(TODAY()-K28)/365,"NA") -> NA | P28: =IF(M28="EOS",(TODAY()-L28)/365,"NA") -> NA | Q28: N | R28: SIT units | S28: 3 | T28: =AJ28+BB28+BS28+CJ28 -> 1.46 | U28: =AK28+BC28+BT28+CK28 -> 51.1 | V28: =AL28+BD28+BU28+CL28 -> 0 | W28: =IF(COUNTA(AC28,AU28,BL28,CC28)=0,"",IF(CC28<>"",CC28,IF(BL28<>"",BL28,IF(AU28<>"",AU28,AC28)))) -> Pass | Y28: =IF(AND(X28<>"", AO28<>""),X28-AO28,0) -> 0 | Z28: 44.6 | AA28: =IF(AK28+BC28+BT28+CK28-Z28>=0,AK28+BC28+BT28+CK28-Z28,0) -> 6.5 | AB28: New Test | AC28: Pass | AD28: APP | AE28: Tianxi | AF28: 3.5.3.2131c | AG28: BIOS: O6WKT1CA OS: 25H2 26200.7462 Driver: v1.0 | AH28: Image build | AJ28: =IF(AK28=0,0,AK28/AQ28/7) -> 1.46 | AK28: 51.1 | AL28: 0 | AM28: NPI | AN28: NPI Team: Bella_Guo Sustain team:Iris_zhou/ Keven_Zhao | AO28: 46111 | AP28: 46126 | AQ28: 5 | AR28: New introduce Tianxi APP | BB28: =IF(BC28=0,0,BC28/BH28/7) -> 0 | BS28: =IF(BT28=0,0,BT28/BY28/7) -> 0
B29: NB往下 | Y29: =IF(AND(X29<>"", AO29<>""),X29-AO29,0) -> 0 | AA29: =IF(AK29+BC29+BT29+CK29-Z29>=0,AK29+BC29+BT29+CK29-Z29,0) -> 0
B30: C38 NB_202605_21 | C30: 2026 | D30: Jun | E30: C38 NB | F30: Gaming | G30: KLG11 | H30: =IFERROR(VLOOKUP(G30,'C38 NB project list'!F:J,2,0),IFERROR(VLOOKUP(G30, 'C38 AIO project list'!E:I,2,0),"")) -> L3X0 17" Intel RPL Refresh HX55 + NV GPU(HPT1&HPT2) | I30: =IFERROR(VLOOKUP(G30,'C38 NB project list'!F:J,4,0),IFERROR(VLOOKUP(G30, 'C38 AIO project list'!E:I,4,0),"")) -> 45811 | J30: =IF(K30<=TODAY(),"Y","N") -> N | K30: =IFERROR(VLOOKUP(G30,'C38 NB project list'!F:J,5,0),IFERROR(VLOOKUP(G30,'C38 AIO project list'!E:I,5,0),"")) -> 46568 | L30: =IF(ISNUMBER(K30),EDATE(K30,60),"") -> 48395 | M30: =IF(COUNT(I30,K30,L30)=0, "", IF(TODAY()<I30,"NPI",IF(TODAY()<K30,"MP",IF(TODAY()<L30,"EOP","EOS")))) -> MP | N30: =IF(M30="MP",(TODAY()-I30)/365,"NA") -> 1.0027397 | O30: =IF(M30="EOP",(TODAY()-#REF!)/365,"NA") -> NA | P30: =IF(M30="EOS",(TODAY()-L30)/365,"NA") -> NA | Q30: N | R30: SIT units | S30: 15 | T30: =AJ30+BB30+BS30+CJ30 -> 0.39047619 | U30: =AK30+BC30+BT30+CK30 -> 41 | V30: =AL30+BD30+BU30+CL30 -> 0 | W30: =IF(COUNTA(AC30,AU30,BL30,CC30)=0,"",IF(CC30<>"",CC30,IF(BL30<>"",BL30,IF(AU30<>"",AU30,AC30)))) -> Planning | Y30: =IF(AND(X30<>"", AO30<>""),X30-AO30,0) -> 0 | Z30: 41 | AA30: =IF(AK30+BC30+BT30+CK30-Z30>=0,AK30+BC30+BT30+CK30-Z30,0) -> 0 | AB30: New Test | AC30: Planning | AD30: Driver | AE30: Wlan Driver | AF30: 24.40.0.4 | AG30: BIOS v44 + Preload v48 | AH30: Image build | AJ30: =IF(AK30=0,0,AK30/AQ30/7) -> 0.39047619 | AK30: 41 | AL30: 0 | AM30: Sustain | AN30: Sustain team: Grace_Zhang/Lily_Ye | AO30: 46168 | AP30: 46188 | AQ30: 15 | AR30: 3.Update Intel BT driver to 24.40.0.3 Change point: Follow Intel wifi driver update to latest version.
B31: C38 NB_202605_20 | C31: 2026 | D31: Jun | E31: C38 NB | F31: Gaming | G31: KLG10 | H31: =IFERROR(VLOOKUP(G31,'C38 NB project list'!F:J,2,0),IFERROR(VLOOKUP(G31, 'C38 AIO project list'!E:I,2,0),"")) -> L3X0 15" Intel RPL Refresh HX55 + NV GPU | I31: =IFERROR(VLOOKUP(G31,'C38 NB project list'!F:J,4,0),IFERROR(VLOOKUP(G31, 'C38 AIO project list'!E:I,4,0),"")) -> 45795 | J31: =IF(K31<=TODAY(),"Y","N") -> N | K31: =IFERROR(VLOOKUP(G31,'C38 NB project list'!F:J,5,0),IFERROR(VLOOKUP(G31,'C38 AIO project list'!E:I,5,0),"")) -> 46568 | L31: =IF(ISNUMBER(K31),EDATE(K31,60),"") -> 48395 | M31: =IF(COUNT(I31,K31,L31)=0, "", IF(TODAY()<I31,"NPI",IF(TODAY()<K31,"MP",IF(TODAY()<L31,"EOP","EOS")))) -> MP | N31: =IF(M31="MP",(TODAY()-I31)/365,"NA") -> 1.0465753 | O31: =IF(M31="EOP",(TODAY()-#REF!)/365,"NA") -> NA | P31: =IF(M31="EOS",(TODAY()-L31)/365,"NA") -> NA | Q31: N | R31: SIT units | S31: 20 | T31: =AJ31+BB31+BS31+CJ31 -> 0.39047619 | U31: =AK31+BC31+BT31+CK31 -> 41 | V31: =AL31+BD31+BU31+CL31 -> 0 | W31: =IF(COUNTA(AC31,AU31,BL31,CC31)=0,"",IF(CC31<>"",CC31,IF(BL31<>"",BL31,IF(AU31<>"",AU31,AC31)))) -> Planning | Y31: =IF(AND(X31<>"", AO31<>""),X31-AO31,0) -> 0 | Z31: 41 | AA31: =IF(AK31+BC31+BT31+CK31-Z31>=0,AK31+BC31+BT31+CK31-Z31,0) -> 0 | AB31: New Test | AC31: Planning | AD31: Driver | AE31: Wlan Driver | AF31: 24.40.0.4 | AG31: BIOS v44 + Preload v48 | AH31: Image build | AJ31: =IF(AK31=0,0,AK31/AQ31/7) -> 0.39047619 | AK31: 41 | AL31: 0 | AM31: Sustain | AN31: Sustain team: Grace_Zhang/Gerry_Xu | AO31: 46168 | AP31: 46188 | AQ31: 15 | AR31: 3.Update Intel BT driver to 24.40.0.3 Change point: Follow Intel wifi driver update to latest version.
B32: C38 NB_202605_19 | C32: 2026 | D32: Jun | E32: C38 NB | F32: Gaming | G32: KLG11 | H32: =IFERROR(VLOOKUP(G32,'C38 NB project list'!F:J,2,0),IFERROR(VLOOKUP(G32, 'C38 AIO project list'!E:I,2,0),"")) -> L3X0 17" Intel RPL Refresh HX55 + NV GPU(HPT1&HPT2) | I32: =IFERROR(VLOOKUP(G32,'C38 NB project list'!F:J,4,0),IFERROR(VLOOKUP(G32, 'C38 AIO project list'!E:I,4,0),"")) -> 45811 | J32: =IF(K32<=TODAY(),"Y","N") -> N | K32: =IFERROR(VLOOKUP(G32,'C38 NB project list'!F:J,5,0),IFERROR(VLOOKUP(G32,'C38 AIO project list'!E:I,5,0),"")) -> 46568 | L32: =IF(ISNUMBER(K32),EDATE(K32,60),"") -> 48395 | M32: =IF(COUNT(I32,K32,L32)=0, "", IF(TODAY()<I32,"NPI",IF(TODAY()<K32,"MP",IF(TODAY()<L32,"EOP","EOS")))) -> MP | N32: =IF(M32="MP",(TODAY()-I32)/365,"NA") -> 1.0027397 | O32: =IF(M32="EOP",(TODAY()-#REF!)/365,"NA") -> NA | P32: =IF(M32="EOS",(TODAY()-L32)/365,"NA") -> NA | Q32: N | R32: SIT units | S32: 15 | T32: =AJ32+BB32+BS32+CJ32 -> 0.2 | U32: =AK32+BC32+BT32+CK32 -> 21 | V32: =AL32+BD32+BU32+CL32 -> 0 | W32: =IF(COUNTA(AC32,AU32,BL32,CC32)=0,"",IF(CC32<>"",CC32,IF(BL32<>"",BL32,IF(AU32<>"",AU32,AC32)))) -> Planning | Y32: =IF(AND(X32<>"", AO32<>""),X32-AO32,0) -> 0 | Z32: 21 | AA32: =IF(AK32+BC32+BT32+CK32-Z32>=0,AK32+BC32+BT32+CK32-Z32,0) -> 0 | AB32: New Test | AC32: Planning | AD32: Driver | AE32: BT Driver | AF32: 24.40.0.3 | AG32: BIOS v44 + Preload v48 | AH32: Image build | AJ32: =IF(AK32=0,0,AK32/AQ32/7) -> 0.2 | AK32: 21 | AL32: 0 | AM32: Sustain | AN32: Sustain team: Grace_Zhang/Lily_Ye | AO32: 46168 | AP32: 46188 | AQ32: 15 | AR32: 2.Update Intel wifi driver to 24.40.0.4 Change point: For security driver update
B33: C38 NB_202605_18 | C33: 2026 | D33: Jun | E33: C38 NB | F33: Gaming | G33: KLG10 | H33: =IFERROR(VLOOKUP(G33,'C38 NB project list'!F:J,2,0),IFERROR(VLOOKUP(G33, 'C38 AIO project list'!E:I,2,0),"")) -> L3X0 15" Intel RPL Refresh HX55 + NV GPU | I33: =IFERROR(VLOOKUP(G33,'C38 NB project list'!F:J,4,0),IFERROR(VLOOKUP(G33, 'C38 AIO project list'!E:I,4,0),"")) -> 45795 | J33: =IF(K33<=TODAY(),"Y","N") -> N | K33: =IFERROR(VLOOKUP(G33,'C38 NB project list'!F:J,5,0),IFERROR(VLOOKUP(G33,'C38 AIO project list'!E:I,5,0),"")) -> 46568 | L33: =IF(ISNUMBER(K33),EDATE(K33,60),"") -> 48395 | M33: =IF(COUNT(I33,K33,L33)=0, "", IF(TODAY()<I33,"NPI",IF(TODAY()<K33,"MP",IF(TODAY()<L33,"EOP","EOS")))) -> MP | N33: =IF(M33="MP",(TODAY()-I33)/365,"NA") -> 1.0465753 | O33: =IF(M33="EOP",(TODAY()-#REF!)/365,"NA") -> NA | P33: =IF(M33="EOS",(TODAY()-L33)/365,"NA") -> NA | Q33: N | R33: SIT units | S33: 20 | T33: =AJ33+BB33+BS33+CJ33 -> 0.2 | U33: =AK33+BC33+BT33+CK33 -> 21 | V33: =AL33+BD33+BU33+CL33 -> 0 | W33: =IF(COUNTA(AC33,AU33,BL33,CC33)=0,"",IF(CC33<>"",CC33,IF(BL33<>"",BL33,IF(AU33<>"",AU33,AC33)))) -> Planning | Y33: =IF(AND(X33<>"", AO33<>""),X33-AO33,0) -> 0 | Z33: 21 | AA33: =IF(AK33+BC33+BT33+CK33-Z33>=0,AK33+BC33+BT33+CK33-Z33,0) -> 0 | AB33: New Test | AC33: Planning | AD33: Driver | AE33: BT Driver | AF33: 24.40.0.3 | AG33: BIOS v44 + Preload v48 | AH33: Image build | AJ33: =IF(AK33=0,0,AK33/AQ33/7) -> 0.2 | AK33: 21 | AL33: 0 | AM33: Sustain | AN33: Sustain team: Grace_Zhang/Gerry_Xu | AO33: 46168 | AP33: 46188 | AQ33: 15 | AR33: 2.Update Intel wifi driver to 24.40.0.4 Change point: For security driver update
B34: C38 NB_202605_17 | C34: 2026 | D34: May | E34: C38 NB | F34: Gaming | G34: KLG20 | H34: =IFERROR(VLOOKUP(G34,'C38 NB project list'!F:J,2,0),IFERROR(VLOOKUP(G34, 'C38 AIO project list'!E:I,2,0),"")) -> L3X0 15" AMD Hawk Point Refresh H45 + NV GPU | I34: =IFERROR(VLOOKUP(G34,'C38 NB project list'!F:J,4,0),IFERROR(VLOOKUP(G34, 'C38 AIO project list'!E:I,4,0),"")) -> 45799 | J34: =IF(K34<=TODAY(),"Y","N") -> N | K34: =IFERROR(VLOOKUP(G34,'C38 NB project list'!F:J,5,0),IFERROR(VLOOKUP(G34,'C38 AIO project list'!E:I,5,0),"")) -> 46568 | L34: =IF(ISNUMBER(K34),EDATE(K34,60),"") -> 48395 | M34: =IF(COUNT(I34,K34,L34)=0, "", IF(TODAY()<I34,"NPI",IF(TODAY()<K34,"MP",IF(TODAY()<L34,"EOP","EOS")))) -> MP | N34: =IF(M34="MP",(TODAY()-I34)/365,"NA") -> 1.0356164 | O34: =IF(M34="EOP",(TODAY()-#REF!)/365,"NA") -> NA | P34: =IF(M34="EOS",(TODAY()-L34)/365,"NA") -> NA | Q34: N | R34: SIT units | S34: 20 | T34: =AJ34+BB34+BS34+CJ34 -> 1.847619 | U34: =AK34+BC34+BT34+CK34 -> 194 | V34: =AL34+BD34+BU34+CL34 -> 93 | W34: =IF(COUNTA(AC34,AU34,BL34,CC34)=0,"",IF(CC34<>"",CC34,IF(BL34<>"",BL34,IF(AU34<>"",AU34,AC34)))) -> Testing | Y34: =IF(AND(X34<>"", AO34<>""),X34-AO34,0) -> 0 | Z34: 194 | AA34: =IF(AK34+BC34+BT34+CK34-Z34>=0,AK34+BC34+BT34+CK34-Z34,0) -> 0 | AB34: New Test | AC34: Testing | AD34: Driver | AE34: VGA Driver | AF34: 32.0.15.959 | AG34: BIOS v26 + Preload v40 | AH34: Image build | AJ34: =IF(AK34=0,0,AK34/AQ34/7) -> 1.847619 | AK34: 194 | AL34: 93 | AM34: Sustain | AN34: Sustain team: Grace_Zhang/Webster_Wang | AO34: 46171 | AP34: 46191 | AQ34: 15 | AR34: 1.Update NVIDIA Video driver to v32.0.15.9595. Change point:For security driver update (Parent id:-LEN-216341)
B35: C38 NB_202605_16 | C35: 2026 | D35: May | E35: C38 NB | F35: Gaming | G35: KLG20 | H35: =IFERROR(VLOOKUP(G35,'C38 NB project list'!F:J,2,0),IFERROR(VLOOKUP(G35, 'C38 AIO project list'!E:I,2,0),"")) -> L3X0 15" AMD Hawk Point Refresh H45 + NV GPU | I35: =IFERROR(VLOOKUP(G35,'C38 NB project list'!F:J,4,0),IFERROR(VLOOKUP(G35, 'C38 AIO project list'!E:I,4,0),"")) -> 45799 | J35: =IF(K35<=TODAY(),"Y","N") -> N | K35: =IFERROR(VLOOKUP(G35,'C38 NB project list'!F:J,5,0),IFERROR(VLOOKUP(G35,'C38 AIO project list'!E:I,5,0),"")) -> 46568 | L35: =IF(ISNUMBER(K35),EDATE(K35,60),"") -> 48395 | M35: =IF(COUNT(I35,K35,L35)=0, "", IF(TODAY()<I35,"NPI",IF(TODAY()<K35,"MP",IF(TODAY()<L35,"EOP","EOS")))) -> MP | N35: =IF(M35="MP",(TODAY()-I35)/365,"NA") -> 1.0356164 | O35: =IF(M35="EOP",(TODAY()-#REF!)/365,"NA") -> NA | P35: =IF(M35="EOS",(TODAY()-L35)/365,"NA") -> NA | Q35: N | R35: SIT units | S35: 15 | T35: =AJ35+BB35+BS35+CJ35 -> 2.6380952 | U35: =AK35+BC35+BT35+CK35 -> 277 | V35: =AL35+BD35+BU35+CL35 -> 93 | W35: =IF(COUNTA(AC35,AU35,BL35,CC35)=0,"",IF(CC35<>"",CC35,IF(BL35<>"",BL35,IF(AU35<>"",AU35,AC35)))) -> Testing | Y35: =IF(AND(X35<>"", AO35<>""),X35-AO35,0) -> 0 | Z35: 277 | AA35: =IF(AK35+BC35+BT35+CK35-Z35>=0,AK35+BC35+BT35+CK35-Z35,0) -> 0 | AB35: New Test | AC35: Testing | AD35: Driver | AE35: VGA Driver | AF35: 32.0.15.959 | AG35: BIOS v26 + Preload v40 | AH35: Image build | AJ35: =IF(AK35=0,0,AK35/AQ35/7) -> 2.6380952 | AK35: 277 | AL35: 93 | AM35: Sustain | AN35: Sustain team: Grace_Zhang/Webster_Wang | AO35: 46171 | AP35: 46191 | AQ35: 15 | AR35: 1.Update NVIDIA Video driver to v32.0.15.9595. Change point:For security driver update (Parent id:-LEN-216341)
B36: C38 NB_202605_15 | C36: 2026 | D36: May | E36: C38 NB | F36: Gaming | G36: KLG11 | H36: =IFERROR(VLOOKUP(G36,'C38 NB project list'!F:J,2,0),IFERROR(VLOOKUP(G36, 'C38 AIO project list'!E:I,2,0),"")) -> L3X0 17" Intel RPL Refresh HX55 + NV GPU(HPT1&HPT2) | I36: =IFERROR(VLOOKUP(G36,'C38 NB project list'!F:J,4,0),IFERROR(VLOOKUP(G36, 'C38 AIO project list'!E:I,4,0),"")) -> 45811 | J36: =IF(K36<=TODAY(),"Y","N") -> N | K36: =IFERROR(VLOOKUP(G36,'C38 NB project list'!F:J,5,0),IFERROR(VLOOKUP(G36,'C38 AIO project list'!E:I,5,0),"")) -> 46568 | L36: =IF(ISNUMBER(K36),EDATE(K36,60),"") -> 48395 | M36: =IF(COUNT(I36,K36,L36)=0, "", IF(TODAY()<I36,"NPI",IF(TODAY()<K36,"MP",IF(TODAY()<L36,"EOP","EOS")))) -> MP | N36: =IF(M36="MP",(TODAY()-I36)/365,"NA") -> 1.0027397 | O36: =IF(M36="EOP",(TODAY()-#REF!)/365,"NA") -> NA | P36: =IF(M36="EOS",(TODAY()-L36)/365,"NA") -> NA | Q36: N | R36: SIT units | S36: 15 | T36: =AJ36+BB36+BS36+CJ36 -> 3.4666667 | U36: =AK36+BC36+BT36+CK36 -> 364 | V36: =AL36+BD36+BU36+CL36 -> 0 | W36: =IF(COUNTA(AC36,AU36,BL36,CC36)=0,"",IF(CC36<>"",CC36,IF(BL36<>"",BL36,IF(AU36<>"",AU36,AC36)))) -> Testing | Y36: =IF(AND(X36<>"", AO36<>""),X36-AO36,0) -> 0 | Z36: 364 | AA36: =IF(AK36+BC36+BT36+CK36-Z36>=0,AK36+BC36+BT36+CK36-Z36,0) -> 0 | AB36: New Test | AC36: Testing | AD36: Driver | AE36: VGA Driver | AF36: 32.0.15.959 | AG36: BIOS v44 + Preload v48 | AH36: Image build | AJ36: =IF(AK36=0,0,AK36/AQ36/7) -> 3.4666667 | AK36: 364 | AL36: 0 | AM36: Sustain | AN36: Sustain team: Grace_Zhang/Lily_Ye | AO36: 46168 | AP36: 46188 | AQ36: 15 | AR36: 1.Update NVIDIA Video driver to v32.0.15.9595. Change point: For security driver update
B37: C38 NB_202605_14 | C37: 2026 | D37: May | E37: C38 NB | F37: Gaming | G37: KLG10 | H37: =IFERROR(VLOOKUP(G37,'C38 NB project list'!F:J,2,0),IFERROR(VLOOKUP(G37, 'C38 AIO project list'!E:I,2,0),"")) -> L3X0 15" Intel RPL Refresh HX55 + NV GPU | I37: =IFERROR(VLOOKUP(G37,'C38 NB project list'!F:J,4,0),IFERROR(VLOOKUP(G37, 'C38 AIO project list'!E:I,4,0),"")) -> 45795 | J37: =IF(K37<=TODAY(),"Y","N") -> N | K37: =IFERROR(VLOOKUP(G37,'C38 NB project list'!F:J,5,0),IFERROR(VLOOKUP(G37,'C38 AIO project list'!E:I,5,0),"")) -> 46568 | L37: =IF(ISNUMBER(K37),EDATE(K37,60),"") -> 48395 | M37: =IF(COUNT(I37,K37,L37)=0, "", IF(TODAY()<I37,"NPI",IF(TODAY()<K37,"MP",IF(TODAY()<L37,"EOP","EOS")))) -> MP | N37: =IF(M37="MP",(TODAY()-I37)/365,"NA") -> 1.0465753 | O37: =IF(M37="EOP",(TODAY()-#REF!)/365,"NA") -> NA | P37: =IF(M37="EOS",(TODAY()-L37)/365,"NA") -> NA | Q37: N | R37: SIT units | S37: 20 | T37: =AJ37+BB37+BS37+CJ37 -> 3.447619 | U37: =AK37+BC37+BT37+CK37 -> 362 | V37: =AL37+BD37+BU37+CL37 -> 0 | W37: =IF(COUNTA(AC37,AU37,BL37,CC37)=0,"",IF(CC37<>"",CC37,IF(BL37<>"",BL37,IF(AU37<>"",AU37,AC37)))) -> Testing | Y37: =IF(AND(X37<>"", AO37<>""),X37-AO37,0) -> 0 | Z37: 362 | AA37: =IF(AK37+BC37+BT37+CK37-Z37>=0,AK37+BC37+BT37+CK37-Z37,0) -> 0 | AB37: New Test | AC37: Testing | AD37: Driver | AE37: VGA Driver | AF37: 32.0.15.959 | AG37: BIOS v44 + Preload v48 | AH37: Image build | AJ37: =IF(AK37=0,0,AK37/AQ37/7) -> 3.447619 | AK37: 362 | AL37: 0 | AM37: Sustain | AN37: Sustain team: Grace_Zhang/Gerry_Xu | AO37: 46168 | AP37: 46188 | AQ37: 15 | AR37: 1.Update NVIDIA Video driver to v32.0.15.9595. Change point: For security driver update
B38: C38 NB_202605_13 | C38: 2026 | D38: May | E38: C38 NB | F38: Gaming | G38: KLG23 | H38: =IFERROR(VLOOKUP(G38,'C38 NB project list'!F:J,2,0),IFERROR(VLOOKUP(G38, 'C38 AIO project list'!E:I,2,0),"")) -> LOQ-E AMD RMB+ + GN22 | I38: 46069 | J38: =IF(K38<=TODAY(),"Y","N") -> N | K38: =IFERROR(VLOOKUP(G38,'C38 NB project list'!F:J,5,0),IFERROR(VLOOKUP(G38,'C38 AIO project list'!E:I,5,0),"")) -> 46843 | L38: =IF(ISNUMBER(K38),EDATE(K38,60),"") -> 48669 | M38: =IF(COUNT(I38,K38,L38)=0, "", IF(TODAY()<I38,"NPI",IF(TODAY()<K38,"MP",IF(TODAY()<L38,"EOP","EOS")))) -> MP | N38: =IF(M38="MP",(TODAY()-I38)/365,"NA") -> 0.29589041 | O38: =IF(M38="EOP",(TODAY()-K38)/365,"NA") -> NA | P38: =IF(M38="EOS",(TODAY()-L38)/365,"NA") -> NA | Q38: N | R38: SIT units | S38: 20 | T38: =AJ38+BB38+BS38+CJ38 -> 2.5238095 | U38: =AK38+BC38+BT38+CK38 -> 265 | V38: =AL38+BD38+BU38+CL38 -> 0 | W38: =IF(COUNTA(AC38,AU38,BL38,CC38)=0,"",IF(CC38<>"",CC38,IF(BL38<>"",BL38,IF(AU38<>"",AU38,AC38)))) -> Testing | Y38: =IF(AND(X38<>"", AO38<>""),X38-AO38,0) -> 0 | Z38: 265 | AA38: =IF(AK38+BC38+BT38+CK38-Z38>=0,AK38+BC38+BT38+CK38-Z38,0) -> 0 | AB38: New Test | AC38: Testing | AD38: Driver | AE38: VGA Driver | AF38: NVIDIA Video driver to v32.0.15.959 | AG38: BIOS V13+Image V19 | AH38: Image build | AJ38: =IF(AK38=0,0,AK38/AQ38/7) -> 2.5238095 | AK38: 265 | AL38: 0 | AM38: Sustain | AN38: Lora_Sun | AO38: 46167 | AP38: 46185 | AQ38: 15 | AR38: 1.Update NVIDIA Video driver to v32.0.15.9595. Change point:For security driver update(Parent id:-LEN-216341)
